Workbook

Sheet Dashboard
A1: Name: | B1: Phuwadol Kongkham
A2: ID: | B2: 6631202026
E3: Trade performance index | F3: 2019 | G3: =+F3+1 -> 2020 | H3: =+G3+1 -> 2021 | I3: =+H3+1 -> 2022 | J3: =+I3+1 -> 2023
A4: Product: | B4: Clothing accessories, of textile fabrics | E4: Finland | F4: 8 | G4: 10 | H4: 8 | I4: 8 | J4: 9
E5: France | F5: 3 | G5: 4 | H5: 3 | I5: 2 | J5: 2
A6: Year: | B6: 2019-2023 | E6: Germany | F6: 2 | G6: 2 | H6: 2 | I6: 3 | J6: 3
E7: Iceland | F7: 10 | G7: 9 | H7: 10 | I7: 10 | J7: 10
A8: Countries: | B8: Finland | E8: Italy | F8: 1 | G8: 1 | H8: 1 | I8: 1 | J8: 1
B9: France | E9: Spain | F9: 5 | G9: 5 | H9: 4 | I9: 5 | J9: 4
B10: Germany | E10: Sweden | F10: 4 | G10: 3 | H10: 5 | I10: 4 | J10: 5
B11: Iceland | E11: Switzerland | F11: 7 | G11: 7 | H11: 7 | I11: 7 | J11: 6
B12: Italy | E12: United Kingdom | F12: 6 | G12: 6 | H12: 9 | I12: 6 | J12: 7
B13: Spain | E13: United States | F13: 9 | G13: 8 | H13: 6 | I13: 9 | J13: 8
B14: Sweden
B15: Switzerland
B16: United Kingdom
B17: United States
E25: Analysis: In 2023, Finland's Trade Performance Index (TPI) ranking declined to 9th place from 8th in 2022, indicating challenges in its export sector. This downward trend reflects broader economic difficulties, as Finland entered a recession with a slow recovery anticipated. BOFBULLETIN.FI A significant factor contributing to this decline is the decrease in Finnish exports, which began to falter at the end of 2022 and continued into 2023. Notably, export growth has been markedly weaker than the growth in Finland’s export markets for two years now. Although Finnish exports increased by slightly over 3.5% in 2022, the growth in Finland’s export markets was a little over 6%. BOFBULLETIN.FI Additionally, Finland's export performance has been affected by external factors such as the war in Ukraine. In 2022, Finnish exports of goods to Russia accounted for 2.6% of total exports, down from 5.4% in 2021, reflecting a significant decrease in trade with Russia. ECONOMY-FINANCE.EC.EUROPA.EU To address these challenges and improve its trade performance, Finland may need to reassess its export strategies, diversify its markets, and enhance the competitiveness of its key industries.
E32: Top 3 Trade Performance index in 2023
E33: In 2023, the top three countries in the Trade Performance Index (TPI) were Italy, Germany, and France, maintaining their strong positions in global trade.
E35: Italy continued to lead the TPI rankings, holding the 1st position consistently from 2019 through 2023. This sustained top ranking underscores Italy's robust export performance and competitive advantage in international markets.
E37: Germany maintained its 3rd position in 2023, reflecting its enduring strength in global trade. Germany's consistent performance highlights its well-established industrial base and export capabilities.
E39: France secured the 2nd position in 2023, improving from its 4th place ranking in 2020. This upward movement indicates France's enhanced trade performance and competitiveness in recent years.
E41: These rankings illustrate the sustained trade competitiveness of these European economies, driven by their diversified export portfolios and strong industrial sectors.

Sheet Trade indicators
A6: Clothing accessories, of textile fabrics | B6: export | H6: import | N6: gdp | V6: Trade openness index (country level) | AE6: Export growth | AN6: Trade competitiveness index | AW6: Revealed comparative advantage index | BE6: Intra-industry trade | BM6: Export diversification | BU6: Export concentration
A7: Economy | B7: 2018 | C7: =+B7+1 -> 2019 | D7: =+C7+1 -> 2020 | E7: =+D7+1 -> 2021 | F7: =+E7+1 -> 2022 | G7: =+F7+1 -> 2023 | H7: 2018 | I7: =+H7+1 -> 2019 | J7: =+I7+1 -> 2020 | K7: =+J7+1 -> 2021 | L7: =+K7+1 -> 2022 | M7: =+L7+1 -> 2023 | N7: 2018 | O7: =+N7+1 -> 2019 | P7: =+O7+1 -> 2020 | Q7: =+P7+1 -> 2021 | R7: =+Q7+1 -> 2022 | S7: =+R7+1 -> 2023 | U7: Economy | V7: 2019 | W7: =+V7+1 -> 2020 | X7: =+W7+1 -> 2021 | Y7: =+X7+1 -> 2022 | Z7: =+Y7+1 -> 2023 | AA7: compound growth rate | AB7: ranking (2023) | AD7: Economy | AE7: 2019 | AF7: =+AE7+1 -> 2020 | AG7: =+AF7+1 -> 2021 | AH7: =+AG7+1 -> 2022 | AI7: =+AH7+1 -> 2023 | AJ7: compound growth rate | AK7: ranking (2023) | AM7: Economy | AN7: 2019 | AO7: =+AN7+1 -> 2020 | AP7: =+AO7+1 -> 2021 | AQ7: =+AP7+1 -> 2022 | AR7: =+AQ7+1 -> 2023 | AS7: compound growth rate | AT7: ranking (2023) | AV7: Economy | AW7: 2019 | AX7: =+AW7+1 -> 2020 | AY7: =+AX7+1 -> 2021 | AZ7: =+AY7+1 -> 2022 | BA7: =+AZ7+1 -> 2023 | BB7: compound growth rate | BD7: Economy | BE7: 2019 | BF7: =+BE7+1 -> 2020 | BG7: =+BF7+1 -> 2021 | BH7: =+BG7+1 -> 2022 | BI7: =+BH7+1 -> 2023 | BJ7: compound growth rate | BL7: Economy | BM7: 2019 | BN7: =+BM7+1 -> 2020 | BO7: =+BN7+1 -> 2021 | BP7: =+BO7+1 -> 2022 | BQ7: =+BP7+1 -> 2023 | BR7: compound growth rate | BT7: Economy | BU7: 2019 | BV7: =+BU7+1 -> 2020 | BW7: =+BV7+1 -> 2021 | BX7: =+BW7+1 -> 2022 | BY7: =+BX7+1 -> 2023 | BZ7: compound growth rate
A8: Finland | B8: 16631 | C8: 18341 | D8: 13752 | E8: 17389 | F8: 18861 | G8: 17560 | H8: 131366 | I8: 123720 | J8: 120628 | K8: 126613 | L8: 151169 | M8: 135024 | N8: 2760000000 | O8: 2690000000 | P8: 2720000000 | Q8: 2970000000 | R8: 2830000000 | S8: 3040000000 | U8: Economy | V8: =(C33+I33)/(O8)*100 -> 5.4482912 | W8: =(D33+J33)/(P8)*100 -> 4.9218198 | X8: =(E33+K33)/(Q8)*100 -> 5.6486141 | Y8: =(F33+L33)/(R8)*100 -> 6.4877277 | Z8: =(G33+M33)/(S8)*100 -> 5.4493871 | AA8: =(Z8/V8)^(1/($Z$7-$V$7))-1 -> 5.0283336e-05 | AB8: =RANK(Z8,$Z$8:$Z$29,0) -> 6 | AD8: Finland | AE8: =(C8-B8)/B8 -> 0.10282003 | AF8: =(D8-C8)/C8 -> -0.25020446 | AG8: =(E8-D8)/D8 -> 0.26447062 | AH8: =(F8-E8)/E8 -> 0.084651216 | AI8: =(G8-F8)/F8 -> -0.068978315 | AJ8: =(G8/B8)^(1/($G$7-$B$7))-1 -> 0.010930337 | AK8: =RANK(AI8,$AI$8:$AI$29,0) -> 9 | AM8: Finland | AN8: =(C8/C$18)*100 -> 0.059274589 | AO8: =(D8/D$18)*100 -> 0.051456765 | AP8: =(E8/E$18)*100 -> 0.055106603 | AQ8: =(F8/F$18)*100 -> 0.055257123 | AR8: =(G8/G$18)*100 -> 0.052678237 | AS8: =(AR8/AN8)^(1/($Z$7-$V$7))-1 -> -0.029063853 | AT8: =RANK(AR8,$AR$8:$AR$29,0) -> 10 | AV8: Finland | AW8: =(C8/C$18)/(C33/C$43) -> 0.14496587 | AX8: =(D8/D$18)/(D33/D$43) -> 0.15203821 | AY8: =(E8/E$18)/(E33/E$43) -> 0.13265385 | AZ8: =(F8/F$18)/(F33/F$43) -> 0.12065341 | BA8: =(G8/G$18)/(G33/G$43) -> 0.12199008 | BB8: =(BA8/AW8)^(1/($Z$7-$V$7))-1 -> -0.04222237 | BD8: Finland | BE8: =1-(ABS(C8-I8)/(C8+I8)) -> 0.25821302 | BF8: =1-(ABS(D8-J8)/(D8+J8)) -> 0.20467331 | BG8: =1-(ABS(E8-K8)/(E8+K8)) -> 0.24151053 | BH8: =1-(ABS(F8-L8)/(F8+L8)) -> 0.22185497 | BI8: =1-(ABS(G8-M8)/(G8+M8)) -> 0.2301683 | BJ8: =(BI8/BE8)^(1/($Z$7-$V$7))-1 -> -0.028334365 | BL8: Finland | BM8: =+H58 -> 0.517 | BN8: =+I58 -> 0.516 | BO8: =+J58 -> 0.522 | BP8: =+K58 -> 0.518 | BQ8: =+L58 -> 0.511 | BR8: =(BQ8/BM8)^(1/($Z$7-$V$7))-1 -> -0.0029140669 | BT8: Finland | BU8: =+C58 -> 0.134 | BV8: =+D58 -> 0.127 | BW8: =+E58 -> 0.128 | BX8: =+F58 -> 0.126 | BY8: =+G58 -> 0.119 | BZ8: =(BY8/BU8)^(1/($Z$7-$V$7))-1 -> -0.029242978
A9: France | B9: 1066042 | C9: 1059057 | D9: 878941 | E9: 1004891 | F9: 1231581 | G9: 1334873 | H9: 1664986 | I9: 1638563 | J9: 1391493 | K9: 1614638 | L9: 1765925 | M9: 1686774 | N9: 27900000000 | O9: 27300000000 | P9: 26500000000 | Q9: 29600000000 | R9: 27800000000 | S9: 30400000000 | U9: Finland | V9: =(C34+I34)/(O9)*100 -> 4.3919414 | W9: =(D34+J34)/(P9)*100 -> 4.0339623 | X9: =(E34+K34)/(Q9)*100 -> 4.3952703 | Y9: =(F34+L34)/(R9)*100 -> 5.1690647 | Z9: =(G34+M34)/(S9)*100 -> 4.6611842 | AA9: =(Z9/V9)^(1/($Z$7-$V$7))-1 -> 0.014985721 | AB9: =RANK(Z9,$Z$8:$Z$29,0) -> 8 | AD9: France | AE9: =(C9-B9)/B9 -> -0.0065522747 | AF9: =(D9-C9)/C9 -> -0.17007205 | AG9: =(E9-D9)/D9 -> 0.14329745 | AH9: =(F9-E9)/E9 -> 0.22558666 | AI9: =(G9-F9)/F9 -> 0.083869433 | AJ9: =(G9/B9)^(1/($G$7-$B$7))-1 -> 0.046003473 | AK9: =RANK(AI9,$AI$8:$AI$29,0) -> 3 | AM9: France | AN9: =(C9/C$18)*100 -> 3.4226688 | AO9: =(D9/D$18)*100 -> 3.2887915 | AP9: =(E9/E$18)*100 -> 3.1845494 | AQ9: =(F9/F$18)*100 -> 3.6081662 | AR9: =(G9/G$18)*100 -> 4.004485 | AS9: =(AR9/AN9)^(1/($Z$7-$V$7))-1 -> 0.040028997 | AT9: =RANK(AR9,$AR$8:$AR$29,0) -> 4 | AV9: France | AW9: =(C9/C$18)/(C34/C$43) -> 1.0966103 | AX9: =(D9/D$18)/(D34/D$43) -> 1.3064019 | AY9: =(E9/E$18)/(E34/E$43) -> 1.0679905 | AZ9: =(F9/F$18)/(F34/F$43) -> 1.0992562 | BA9: =(G9/G$18)/(G34/G$43) -> 1.1963836 | BB9: =(BA9/AW9)^(1/($Z$7-$V$7))-1 -> 0.022008558 | BD9: France | BE9: =1-(ABS(C9-I9)/(C9+I9)) -> 0.78517879 | BF9: =1-(ABS(D9-J9)/(D9+J9)) -> 0.77424933 | BG9: =1-(ABS(E9-K9)/(E9+K9)) -> 0.76723029 | BH9: =1-(ABS(F9-L9)/(F9+L9)) -> 0.82173714 | BI9: =1-(ABS(G9-M9)/(G9+M9)) -> 0.88354 | BJ9: =(BI9/BE9)^(1/($Z$7-$V$7))-1 -> 0.029945904 | BL9: France | BM9: =+H59 -> 0.333 | BN9: =+I59 -> 0.335 | BO9: =+J59 -> 0.33 | BP9: =+K59 -> 0.329 | BQ9: =+L59 -> 0.332 | BR9: =(BQ9/BM9)^(1/($Z$7-$V$7))-1 -> -0.00075159767 | BT9: France | BU9: =+C59 -> 0.093 | BV9: =+D59 -> 0.08 | BW9: =+E59 -> 0.068 | BX9: =+F59 -> 0.065 | BY9: =+G59 -> 0.07 | BZ9: =(BY9/BU9)^(1/($Z$7-$V$7))-1 -> -0.068562384
A10: Germany | B10: 1235367 | C10: 1242332 | D10: 1150003 | E10: 1331890 | F10: 1384510 | G10: 1365252 | H10: 2165479 | I10: 2076944 | J10: 1974367 | K10: 2225359 | L10: 2483835 | M10: 2144477 | N10: 39700000000 | O10: 38900000000 | P10: 38900000000 | Q10: 42800000000 | R10: 40800000000 | S10: 44600000000 | U10: France | V10: =(C35+I35)/(O10)*100 -> 7.0179949 | W10: =(D35+J35)/(P10)*100 -> 6.5809769 | X10: =(E35+K35)/(Q10)*100 -> 7.1495327 | Y10: =(F35+L35)/(R10)*100 -> 8.0392157 | Z10: =(G35+M35)/(S10)*100 -> 7.1076233 | AA10: =(Z10/V10)^(1/($Z$7-$V$7))-1 -> 0.0031776306 | AB10: =RANK(Z10,$Z$8:$Z$29,0) -> 2 | AD10: Germany | AE10: =(C10-B10)/B10 -> 0.0056380007 | AF10: =(D10-C10)/C10 -> -0.074319103 | AG10: =(E10-D10)/D10 -> 0.1581622 | AH10: =(F10-E10)/E10 -> 0.039507767 | AI10: =(G10-F10)/F10 -> -0.013909614 | AJ10: =(G10/B10)^(1/($G$7-$B$7))-1 -> 0.02019541 | AK10: =RANK(AI10,$AI$8:$AI$29,0) -> 6 | AM10: Germany | AN10: =(C10/C$18)*100 -> 4.0149784 | AO10: =(D10/D$18)*100 -> 4.303042 | AP10: =(E10/E$18)*100 -> 4.2208255 | AQ10: =(F10/F$18)*100 -> 4.0562027 | AR10: =(G10/G$18)*100 -> 4.0956189 | AS10: =(AR10/AN10)^(1/($Z$7-$V$7))-1 -> 0.0049838482 | AT10: =RANK(AR10,$AR$8:$AR$29,0) -> 3 | AV10: Germany | AW10: =(C10/C$18)/(C35/C$43) -> 0.48001984 | AX10: =(D10/D$18)/(D35/D$43) -> 0.60009648 | AY10: =(E10/E$18)/(E35/E$43) -> 0.50492724 | AZ10: =(F10/F$18)/(F35/F$43) -> 0.45189113 | BA10: =(G10/G$18)/(G35/G$43) -> 0.4606535 | BB10: =(BA10/AW10)^(1/($Z$7-$V$7))-1 -> -0.010242506 | BD10: Germany | BE10: =1-(ABS(C10-I10)/(C10+I10)) -> 0.74855601 | BF10: =1-(ABS(D10-J10)/(D10+J10)) -> 0.73615033 | BG10: =1-(ABS(E10-K10)/(E10+K10)) -> 0.74883147 | BH10: =1-(ABS(F10-L10)/(F10+L10)) -> 0.71581516 | BI10: =1-(ABS(G10-M10)/(G10+M10)) -> 0.77798143 | BJ10: =(BI10/BE10)^(1/($Z$7-$V$7))-1 -> 0.0096857635 | BL10: Germany | BM10: =+H60 -> 0.311 | BN10: =+I60 -> 0.304 | BO10: =+J60 -> 0.293 | BP10: =+K60 -> 0.303 | BQ10: =+L60 -> 0.325 | BR10: =(BQ10/BM10)^(1/($Z$7-$V$7))-1 -> 0.011068879 | BT10: Germany | BU10: =+C60 -> 0.091 | BV10: =+D60 -> 0.085 | BW10: =+E60 -> 0.082 | BX10: =+F60 -> 0.088 | BY10: =+G60 -> 0.097 | BZ10: =(BY10/BU10)^(1/($Z$7-$V$7))-1 -> 0.016090955
A11: Iceland | B11: 190 | C11: 233 | D11: 248 | E11: 371 | F11: 354 | G11: 402 | H11: 14753 | I11: 13412 | J11: 13906 | K11: 19345 | L11: 20930 | M11: 19783 | N11: 263000000 | O11: 247000000 | P11: 216000000 | Q11: 256000000 | R11: 281000000 | S11: 304000000 | U11: Germany | V11: =(C36+I36)/(O11)*100 -> 4.7803097 | W11: =(D36+J36)/(P11)*100 -> 4.7579144 | X11: =(E36+K36)/(Q11)*100 -> 5.3952402 | Y11: =(F36+L36)/(R11)*100 -> 6.0668114 | Z11: =(G36+M36)/(S11)*100 -> 5.3545036 | AA11: =(Z11/V11)^(1/($Z$7-$V$7))-1 -> 0.028764087 | AB11: =RANK(Z11,$Z$8:$Z$29,0) -> 7 | AD11: Iceland | AE11: =(C11-B11)/B11 -> 0.22631579 | AF11: =(D11-C11)/C11 -> 0.064377682 | AG11: =(E11-D11)/D11 -> 0.49596774 | AH11: =(F11-E11)/E11 -> -0.045822102 | AI11: =(G11-F11)/F11 -> 0.13559322 | AJ11: =(G11/B11)^(1/($G$7-$B$7))-1 -> 0.16170134 | AK11: =RANK(AI11,$AI$8:$AI$29,0) -> 2 | AM11: Iceland | AN11: =(C11/C$18)*100 -> 0.00075301125 | AO11: =(D11/D$18)*100 -> 0.00092795795 | AP11: =(E11/E$18)*100 -> 0.0011757174 | AQ11: =(F11/F$18)*100 -> 0.0010371148 | AR11: =(G11/G$18)*100 -> 0.0012059596 | AS11: =(AR11/AN11)^(1/($Z$7-$V$7))-1 -> 0.12494898 | AT11: =RANK(AR11,$AR$8:$AR$29,0) -> 11 | AV11: Iceland | AW11: =(C11/C$18)/(C36/C$43) -> 0.025656543 | AX11: =(D11/D$18)/(D36/D$43) -> 0.039272067 | AY11: =(E11/E$18)/(E36/E$43) -> 0.038612833 | AZ11: =(F11/F$18)/(F36/F$43) -> 0.026373829 | BA11: =(G11/G$18)/(G36/G$43) -> 0.033872428 | BB11: =(BA11/AW11)^(1/($Z$7-$V$7))-1 -> 0.071919197 | BD11: Iceland | BE11: =1-(ABS(C11-I11)/(C11+I11)) -> 0.034151704 | BF11: =1-(ABS(D11-J11)/(D11+J11)) -> 0.035043097 | BG11: =1-(ABS(E11-K11)/(E11+K11)) -> 0.037634409 | BH11: =1-(ABS(F11-L11)/(F11+L11)) -> 0.033264424 | BI11: =1-(ABS(G11-M11)/(G11+M11)) -> 0.039831558 | BJ11: =(BI11/BE11)^(1/($Z$7-$V$7))-1 -> 0.039210987 | BL11: Iceland | BM11: =+H61 -> 0.793 | BN11: =+I61 -> 0.793 | BO11: =+J61 -> 0.824 | BP11: =+K61 -> 0.8 | BQ11: =+L61 -> 0.783 | BR11: =(BQ11/BM11)^(1/($Z$7-$V$7))-1 -> -0.0031676039 | BT11: Iceland | BU11: =+C61 -> 0.442 | BV11: =+D61 -> 0.466 | BW11: =+E61 -> 0.48 | BX11: =+F61 -> 0.466 | BY11: =+G61 -> 0.432 | BZ11: =(BY11/BU11)^(1/($Z$7-$V$7))-1 -> -0.0057047393
A12: Italy | B12: 2309922 | C12: 2346768 | D12: 2128995 | E12: 2537671 | F12: 2564253 | G12: 2526168 | H12: 947446 | I12: 941968 | J12: 753652 | K12: 871162 | L12: 1005447 | M12: 1017704 | N12: 20900000000 | O12: 20100000000 | P12: 19000000000 | Q12: 21600000000 | R12: 20500000000 | S12: 22300000000 | U12: Iceland | V12: =(C37+I37)/(O12)*100 -> 5.039801 | W12: =(D37+J37)/(P12)*100 -> 4.8684211 | X12: =(E37+K37)/(Q12)*100 -> 5.4814815 | Y12: =(F37+L37)/(R12)*100 -> 6.604878 | Z12: =(G37+M37)/(S12)*100 -> 5.9058296 | AA12: =(Z12/V12)^(1/($Z$7-$V$7))-1 -> 0.040439618 | AB12: =RANK(Z12,$Z$8:$Z$29,0) -> 4 | AD12: Italy | AE12: =(C12-B12)/B12 -> 0.015951188 | AF12: =(D12-C12)/C12 -> -0.092796987 | AG12: =(E12-D12)/D12 -> 0.19195724 | AH12: =(F12-E12)/E12 -> 0.010474959 | AI12: =(G12-F12)/F12 -> -0.014852279 | AJ12: =(G12/B12)^(1/($G$7-$B$7))-1 -> 0.018059083 | AK12: =RANK(AI12,$AI$8:$AI$29,0) -> 7 | AM12: Italy | AN12: =(C12/C$18)*100 -> 7.5843034 | AO12: =(D12/D$18)*100 -> 7.9662009 | AP12: =(E12/E$18)*100 -> 8.0420052 | AQ12: =(F12/F$18)*100 -> 7.512499 | AR12: =(G12/G$18)*100 -> 7.5782504 | AS12: =(AR12/AN12)^(1/($Z$7-$V$7))-1 -> -0.00019958533 | AT12: =RANK(AR12,$AR$8:$AR$29,0) -> 2 | AV12: Italy | AW12: =(C12/C$18)/(C37/C$43) -> 2.511283 | AX12: =(D12/D$18)/(D37/D$43) -> 3.0946462 | AY12: =(E12/E$18)/(E37/E$43) -> 2.5612908 | AZ12: =(F12/F$18)/(F37/F$43) -> 2.1463467 | BA12: =(G12/G$18)/(G37/G$43) -> 2.1403463 | BB12: =(BA12/AW12)^(1/($Z$7-$V$7))-1 -> -0.039168806 | BD12: Italy | BE12: =1-(ABS(C12-I12)/(C12+I12)) -> 0.57284501 | BF12: =1-(ABS(D12-J12)/(D12+J12)) -> 0.52288886 | BG12: =1-(ABS(E12-K12)/(E12+K12)) -> 0.51112037 | BH12: =1-(ABS(F12-L12)/(F12+L12)) -> 0.56332297 | BI12: =1-(ABS(G12-M12)/(G12+M12)) -> 0.5743458 | BJ12: =(BI12/BE12)^(1/($Z$7-$V$7))-1 -> 0.00065433063 | BL12: Italy | BM12: =+H62 -> 0.357 | BN12: =+I62 -> 0.355 | BO12: =+J62 -> 0.345 | BP12: =+K62 -> 0.353 | BQ12: =+L62 -> 0.366 | BR12: =(BQ12/BM12)^(1/($Z$7-$V$7))-1 -> 0.0062437997 | BT12: Italy | BU12: =+C62 -> 0.056 | BV12: =+D62 -> 0.058 | BW12: =+E62 -> 0.053 | BX12: =+F62 -> 0.06 | BY12: =+G62 -> 0.062 | BZ12: =(BY12/BU12)^(1/($Z$7-$V$7))-1 -> 0.025772178
A13: Spain | B13: 441646 | C13: 391782 | D13: 295092 | E13: 375671 | F13: 396316 | G13: 419105 | H13: 684383 | I13: 674709 | J13: 524195 | K13: 618840 | L13: 726883 | M13: 686366 | N13: 14200000000 | O13: 13900000000 | P13: 12800000000 | Q13: 14500000000 | R13: 14200000000 | S13: 16000000000 | U13: Italy | V13: =(C38+I38)/(O13)*100 -> 5.1223022 | W13: =(D38+J38)/(P13)*100 -> 5.015625 | X13: =(E38+K38)/(Q13)*100 -> 5.6413793 | Y13: =(F38+L38)/(R13)*100 -> 6.5 | Z13: =(G38+M38)/(S13)*100 -> 5.55625 | AA13: =(Z13/V13)^(1/($Z$7-$V$7))-1 -> 0.02053792 | AB13: =RANK(Z13,$Z$8:$Z$29,0) -> 5 | AD13: Spain | AE13: =(C13-B13)/B13 -> -0.11290491 | AF13: =(D13-C13)/C13 -> -0.24679541 | AG13: =(E13-D13)/D13 -> 0.27306399 | AH13: =(F13-E13)/E13 -> 0.054955001 | AI13: =(G13-F13)/F13 -> 0.057502094 | AJ13: =(G13/B13)^(1/($G$7-$B$7))-1 -> -0.010422737 | AK13: =RANK(AI13,$AI$8:$AI$29,0) -> 4 | AM13: Spain | AN13: =(C13/C$18)*100 -> 1.2661642 | AO13: =(D13/D$18)*100 -> 1.1041652 | AP13: =(E13/E$18)*100 -> 1.19052 | AQ13: =(F13/F$18)*100 -> 1.1610881 | AR13: =(G13/G$18)*100 -> 1.2572729 | AS13: =(AR13/AN13)^(1/($Z$7-$V$7))-1 -> -0.0017601906 | AT13: =RANK(AR13,$AR$8:$AR$29,0) -> 6 | AV13: Spain | AW13: =(C13/C$18)/(C38/C$43) -> 0.66930236 | AX13: =(D13/D$18)/(D38/D$43) -> 0.6860247 | AY13: =(E13/E$18)/(E38/E$43) -> 0.59583484 | AZ13: =(F13/F$18)/(F38/F$43) -> 0.51558488 | BA13: =(G13/G$18)/(G38/G$43) -> 0.57237945 | BB13: =(BA13/AW13)^(1/($Z$7-$V$7))-1 -> -0.038353583 | BD13: Spain | BE13: =1-(ABS(C13-I13)/(C13+I13)) -> 0.73471225 | BF13: =1-(ABS(D13-J13)/(D13+J13)) -> 0.72036295 | BG13: =1-(ABS(E13-K13)/(E13+K13)) -> 0.75548888 | BH13: =1-(ABS(F13-L13)/(F13+L13)) -> 0.70569151 | BI13: =1-(ABS(G13-M13)/(G13+M13)) -> 0.75823789 | BJ13: =(BI13/BE13)^(1/($Z$7-$V$7))-1 -> 0.007910689 | BL13: Spain | BM13: =+H63 -> 0.341 | BN13: =+I63 -> 0.342 | BO13: =+J63 -> 0.358 | BP13: =+K63 -> 0.355 | BQ13: =+L63 -> 0.354 | BR13: =(BQ13/BM13)^(1/($Z$7-$V$7))-1 -> 0.0093974907 | BT13: Spain | BU13: =+C63 -> 0.099 | BV13: =+D63 -> 0.099 | BW13: =+E63 -> 0.089 | BX13: =+F63 -> 0.09 | BY13: =+G63 -> 0.092 | BZ13: =(BY13/BU13)^(1/($Z$7-$V$7))-1 -> -0.018165794
A14: Sweden | B14: 133842 | C14: 151377 | D14: 152586 | E14: 188624 | F14: 203400 | G14: 206730 | H14: 283672 | I14: 283450 | J14: 253210 | K14: 324893 | L14: 344610 | M14: 311660 | N14: 5550000000 | O14: 5340000000 | P14: 5470000000 | Q14: 6400000000 | R14: 5910000000 | S14: 5900000000 | U14: Spain | V14: =(C39+I39)/(O14)*100 -> 5.9925094 | W14: =(D39+J39)/(P14)*100 -> 5.5575868 | X14: =(E39+K39)/(Q14)*100 -> 5.890625 | Y14: =(F39+L39)/(R14)*100 -> 6.78511 | Z14: =(G39+M39)/(S14)*100 -> 6.6271186 | AA14: =(Z14/V14)^(1/($Z$7-$V$7))-1 -> 0.025484277 | AB14: =RANK(Z14,$Z$8:$Z$29,0) -> 3 | AD14: Sweden | AE14: =(C14-B14)/B14 -> 0.13101269 | AF14: =(D14-C14)/C14 -> 0.0079866823 | AG14: =(E14-D14)/D14 -> 0.23618156 | AH14: =(F14-E14)/E14 -> 0.078335737 | AI14: =(G14-F14)/F14 -> 0.016371681 | AJ14: =(G14/B14)^(1/($G$7-$B$7))-1 -> 0.09084292 | AK14: =RANK(AI14,$AI$8:$AI$29,0) -> 5 | AM14: Sweden | AN14: =(C14/C$18)*100 -> 0.48922139 | AO14: =(D14/D$18)*100 -> 0.57094109 | AP14: =(E14/E$18)*100 -> 0.59775881 | AQ14: =(F14/F$18)*100 -> 0.59590153 | AR14: =(G14/G$18)*100 -> 0.62016924 | AS14: =(AR14/AN14)^(1/($Z$7-$V$7))-1 -> 0.061087497 | AT14: =RANK(AR14,$AR$8:$AR$29,0) -> 8 | AV14: Sweden | AW14: =(C14/C$18)/(C39/C$43) -> 0.5413047 | AX14: =(D14/D$18)/(D39/D$43) -> 0.71403565 | AY14: =(E14/E$18)/(E39/E$43) -> 0.61723087 | AZ14: =(F14/F$18)/(F39/F$43) -> 0.56664385 | BA14: =(G14/G$18)/(G39/G$43) -> 0.59889239 | BB14: =(BA14/AW14)^(1/($Z$7-$V$7))-1 -> 0.025597016 | BD14: Sweden | BE14: =1-(ABS(C14-I14)/(C14+I14)) -> 0.69626311 | BF14: =1-(ABS(D14-J14)/(D14+J14)) -> 0.75203304 | BG14: =1-(ABS(E14-K14)/(E14+K14)) -> 0.73463585 | BH14: =1-(ABS(F14-L14)/(F14+L14)) -> 0.74232222 | BI14: =1-(ABS(G14-M14)/(G14+M14)) -> 0.79758483 | BJ14: =(BI14/BE14)^(1/($Z$7-$V$7))-1 -> 0.034548546 | BL14: Sweden | BM14: =+H64 -> 0.361 | BN14: =+I64 -> 0.354 | BO14: =+J64 -> 0.347 | BP14: =+K64 -> 0.353 | BQ14: =+L64 -> 0.37 | BR14: =(BQ14/BM14)^(1/($Z$7-$V$7))-1 -> 0.0061752506 | BT14: Sweden | BU14: =+C64 -> 0.096 | BV14: =+D64 -> 0.093 | BW14: =+E64 -> 0.088 | BX14: =+F64 -> 0.092 | BY14: =+G64 -> 0.095 | BZ14: =(BY14/BU14)^(1/($Z$7-$V$7))-1 -> -0.0026144015
A15: Switzerland | B15: 86131 | C15: 82723 | D15: 78069 | E15: 90450 | F15: 84715 | G15: 106610 | H15: 355623 | I15: 347148 | J15: 338543 | K15: 392750 | L15: 394320 | M15: 403220 | N15: 7260000000 | O15: 7210000000 | P15: 7420000000 | Q15: 8130000000 | R15: 8180000000 | S15: 8870000000 | U15: Sweden | V15: =(C40+I40)/(O15)*100 -> 8.1830791 | W15: =(D40+J40)/(P15)*100 -> 8.2075472 | X15: =(E40+K40)/(Q15)*100 -> 8.6469865 | Y15: =(F40+L40)/(R15)*100 -> 9.2420538 | Z15: =(G40+M40)/(S15)*100 -> 8.8500564 | AA15: =(Z15/V15)^(1/($Z$7-$V$7))-1 -> 0.019781954 | AB15: =RANK(Z15,$Z$8:$Z$29,0) -> 1 | AD15: Switzerland | AE15: =(C15-B15)/B15 -> -0.039567635 | AF15: =(D15-C15)/C15 -> -0.056260049 | AG15: =(E15-D15)/D15 -> 0.15859048 | AH15: =(F15-E15)/E15 -> -0.063405196 | AI15: =(G15-F15)/F15 -> 0.25845482 | AJ15: =(G15/B15)^(1/($G$7-$B$7))-1 -> 0.04358467 | AK15: =RANK(AI15,$AI$8:$AI$29,0) -> 1 | AM15: Switzerland | AN15: =(C15/C$18)*100 -> 0.26734485 | AO15: =(D15/D$18)*100 -> 0.29211592 | AP15: =(E15/E$18)*100 -> 0.28664054 | AQ15: =(F15/F$18)*100 -> 0.24818977 | AR15: =(G15/G$18)*100 -> 0.3198193 | AS15: =(AR15/AN15)^(1/($Z$7-$V$7))-1 -> 0.045823055 | AT15: =RANK(AR15,$AR$8:$AR$29,0) -> 9 | AV15: Switzerland | AW15: =(C15/C$18)/(C40/C$43) -> 0.15167165 | AX15: =(D15/D$18)/(D40/D$43) -> 0.17751082 | AY15: =(E15/E$18)/(E40/E$43) -> 0.14798894 | AZ15: =(F15/F$18)/(F40/F$43) -> 0.11682203 | BA15: =(G15/G$18)/(G40/G$43) -> 0.14559925 | BB15: =(BA15/AW15)^(1/($Z$7-$V$7))-1 -> -0.010163007 | BD15: Switzerland | BE15: =1-(ABS(C15-I15)/(C15+I15)) -> 0.3848736 | BF15: =1-(ABS(D15-J15)/(D15+J15)) -> 0.37478037 | BG15: =1-(ABS(E15-K15)/(E15+K15)) -> 0.37437914 | BH15: =1-(ABS(F15-L15)/(F15+L15)) -> 0.35369023 | BI15: =1-(ABS(G15-M15)/(G15+M15)) -> 0.41821784 | BJ15: =(BI15/BE15)^(1/($Z$7-$V$7))-1 -> 0.020989103 | BL15: Switzerland | BM15: =+H65 -> 0.636 | BN15: =+I65 -> 0.64 | BO15: =+J65 -> 0.644 | BP15: =+K65 -> 0.66 | BQ15: =+L65 -> 0.674 | BR15: =(BQ15/BM15)^(1/($Z$7-$V$7))-1 -> 0.014613637 | BT15: Switzerland | BU15: =+C65 -> 0.25 | BV15: =+D65 -> 0.273 | BW15: =+E65 -> 0.271 | BX15: =+F65 -> 0.28 | BY15: =+G65 -> 0.286 | BZ15: =(BY15/BU15)^(1/($Z$7-$V$7))-1 -> 0.034204698
A16: United Kingdom | B16: 541081 | C16: 459894 | D16: 379554 | E16: 316230 | F16: 350769 | G16: 315593 | H16: 1433783 | I16: 1395023 | J16: 1102364 | K16: 1099676 | L16: 1297276 | M16: 1188177 | N16: 28700000000 | O16: 28500000000 | P16: 27000000000 | Q16: 31400000000 | R16: 30900000000 | S16: 33400000000 | U16: Switzerland | V16: =(C41+I41)/(O16)*100 -> 4.0701754 | W16: =(D41+J41)/(P16)*100 -> 3.8148148 | X16: =(E41+K41)/(Q16)*100 -> 3.6910828 | Y16: =(F41+L41)/(R16)*100 -> 4.3915858 | Z16: =(G41+M41)/(S16)*100 -> 3.9311377 | AA16: =(Z16/V16)^(1/($Z$7-$V$7))-1 -> -0.0086516627 | AB16: =RANK(Z16,$Z$8:$Z$29,0) -> 10 | AD16: United Kingdom | AE16: =(C16-B16)/B16 -> -0.15004593 | AF16: =(D16-C16)/C16 -> -0.17469243 | AG16: =(E16-D16)/D16 -> -0.16683792 | AH16: =(F16-E16)/E16 -> 0.10922114 | AI16: =(G16-F16)/F16 -> -0.10028252 | AJ16: =(G16/B16)^(1/($G$7-$B$7))-1 -> -0.10221361 | AK16: =RANK(AI16,$AI$8:$AI$29,0) -> 11 | AM16: United Kingdom | AN16: =(C16/C$18)*100 -> 1.4862891 | AO16: =(D16/D$18)*100 -> 1.4202022 | AP16: =(E16/E$18)*100 -> 1.0021486 | AQ16: =(F16/F$18)*100 -> 1.0276489 | AR16: =(G16/G$18)*100 -> 0.94674731 | AS16: =(AR16/AN16)^(1/($Z$7-$V$7))-1 -> -0.10662725 | AT16: =RANK(AR16,$AR$8:$AR$29,0) -> 7 | AV16: United Kingdom | AW16: =(C16/C$18)/(C41/C$43) -> 0.56574363 | AX16: =(D16/D$18)/(D41/D$43) -> 0.69520886 | AY16: =(E16/E$18)/(E41/E$43) -> 0.41743268 | AZ16: =(F16/F$18)/(F41/F$43) -> 0.36165281 | BA16: =(G16/G$18)/(G41/G$43) -> 0.34745624 | BB16: =(BA16/AW16)^(1/($Z$7-$V$7))-1 -> -0.11474149 | BD16: United Kingdom | BE16: =1-(ABS(C16-I16)/(C16+I16)) -> 0.49586477 | BF16: =1-(ABS(D16-J16)/(D16+J16)) -> 0.51224697 | BG16: =1-(ABS(E16-K16)/(E16+K16)) -> 0.4466822 | BH16: =1-(ABS(F16-L16)/(F16+L16)) -> 0.42567891 | BI16: =1-(ABS(G16-M16)/(G16+M16)) -> 0.41973573 | BJ16: =(BI16/BE16)^(1/($Z$7-$V$7))-1 -> -0.04081325 | BL16: United Kingdom | BM16: =+H66 -> 0.324 | BN16: =+I66 -> 0.32 | BO16: =+J66 -> 0.323 | BP16: =+K66 -> 0.365 | BQ16: =+L66 -> 0.372 | BR16: =(BQ16/BM16)^(1/($Z$7-$V$7))-1 -> 0.035140933 | BT16: United Kingdom | BU16: =+C66 -> 0.105 | BV16: =+D66 -> 0.097 | BW16: =+E66 -> 0.114 | BX16: =+F66 -> 0.14 | BY16: =+G66 -> 0.139 | BZ16: =(BY16/BU16)^(1/($Z$7-$V$7))-1 -> 0.072645896
A17: United States | B17: 834742 | C17: 765234 | D17: 545955 | E17: 783508 | F17: 556503 | G17: 501466 | H17: 4932472 | I17: 5068165 | J17: 4381239 | K17: 5154804 | L17: 5615233 | M17: 4646194 | N17: 207000000000 | O17: 215000000000 | P17: 213000000000 | Q17: 236000000000 | R17: 257000000000 | S17: 273000000000 | U17: United Kingdom | V17: =(C42+I42)/(O17)*100 -> 1.9581395 | W17: =(D42+J42)/(P17)*100 -> 1.8028169 | X17: =(E42+K42)/(Q17)*100 -> 1.9830508 | Y17: =(F42+L42)/(R17)*100 -> 2.1128405 | Z17: =(G42+M42)/(S17)*100 -> 1.9010989 | AA17: =(Z17/V17)^(1/($Z$7-$V$7))-1 -> -0.0073634355 | AB17: =RANK(Z17,$Z$8:$Z$29,0) -> 11 | AD17: United States | AE17: =(C17-B17)/B17 -> -0.083268842 | AF17: =(D17-C17)/C17 -> -0.28655156 | AG17: =(E17-D17)/D17 -> 0.43511462 | AH17: =(F17-E17)/E17 -> -0.28972901 | AI17: =(G17-F17)/F17 -> -0.098897939 | AJ17: =(G17/B17)^(1/($G$7-$B$7))-1 -> -0.096895835 | AK17: =RANK(AI17,$AI$8:$AI$29,0) -> 10 | AM17: United States | AN17: =(C17/C$18)*100 -> 2.4730893 | AO17: =(D17/D$18)*100 -> 2.0428358 | AP17: =(E17/E$18)*100 -> 2.4829757 | AQ17: =(F17/F$18)*100 -> 1.6303884 | AR17: =(G17/G$18)*100 -> 1.5043476 | AS17: =(AR17/AN17)^(1/($Z$7-$V$7))-1 -> -0.11686499 | AT17: =RANK(AR17,$AR$8:$AR$29,0) -> 5 | AV17: United States | AW17: =(C17/C$18)/(C42/C$43) -> 0.26863228 | AX17: =(D17/D$18)/(D42/D$43) -> 0.27692217 | AY17: =(E17/E$18)/(E42/E$43) -> 0.27836182 | AZ17: =(F17/F$18)/(F42/F$43) -> 0.14901319 | BA17: =(G17/G$18)/(G42/G$43) -> 0.14239692 | BB17: =(BA17/AW17)^(1/($Z$7-$V$7))-1 -> -0.14673172 | BD17: United States | BE17: =1-(ABS(C17-I17)/(C17+I17)) -> 0.26236299 | BF17: =1-(ABS(D17-J17)/(D17+J17)) -> 0.22160889 | BG17: =1-(ABS(E17-K17)/(E17+K17)) -> 0.2638824 | BH17: =1-(ABS(F17-L17)/(F17+L17)) -> 0.18033921 | BI17: =1-(ABS(G17-M17)/(G17+M17)) -> 0.1948326 | BJ17: =(BI17/BE17)^(1/($Z$7-$V$7))-1 -> -0.071696975 | BL17: United States | BM17: =+H67 -> 0.24 | BN17: =+I67 -> 0.23 | BO17: =+J67 -> 0.232 | BP17: =+K67 -> 0.228 | BQ17: =+L67 -> 0.219 | BR17: =(BQ17/BM17)^(1/($Z$7-$V$7))-1 -> -0.022631769 | BT17: United States | BU17: =+C67 -> 0.101 | BV17: =+D67 -> 0.083 | BW17: =+E67 -> 0.083 | BX17: =+F67 -> 0.094 | BY17: =+G67 -> 0.097 | BZ17: =(BY17/BU17)^(1/($Z$7-$V$7))-1 -> -0.010051527
A18: World | B18: 31202744 | C18: 30942433 | D18: 26725349 | E18: 31555202 | F18: 34133156 | G18: 33334449 | H18: 28536824 | I18: 28219851 | J18: 24176100 | K18: 28488059 | L18: 31107220 | M18: 29072852 | N18: 866000000000 | O18: 877000000000 | P18: 855000000000 | Q18: 973000000000 | R18: 1010000000000 | S18: 1050000000000 | U18: World | V18: =(C43+I43)/(O18)*100 -> 4.0497883 | W18: =(D43+J43)/(P18)*100 -> 4.8696466 | X18: =(E43+K43)/(Q18)*100 -> 4.3269885 | Y18: =(F43+L43)/(R18)*100 -> 4.3186415 | Z18: =(G43+M43)/(S18)*100 -> 4.2479429 | AA18: =(Z18/V18)^(1/($Z$7-$V$7))-1 -> 0.012014153 | AD18: World | AE18: =(C18-B18)/B18 -> -0.0083425676 | AF18: =(D18-C18)/C18 -> -0.13628805 | AG18: =(E18-D18)/D18 -> 0.18072179 | AH18: =(F18-E18)/E18 -> 0.081696641 | AI18: =(G18-F18)/F18 -> -0.023399741 | AJ18: =(G18/B18)^(1/($G$7-$B$7))-1 -> 0.013304797 | AM18: World | AN18: =(C18/C$18)*100 -> 100 | AO18: =(D18/D$18)*100 -> 100 | AP18: =(E18/E$18)*100 -> 100 | AQ18: =(F18/F$18)*100 -> 100 | AR18: =(G18/G$18)*100 -> 100 | AV18: World | AW18: =(B18/B43)/(B$18/B$43) -> 1 | AX18: =(C18/C43)/(C$18/C$43) -> 1 | AY18: =(D18/D43)/(D$18/D$43) -> 1 | AZ18: =(E18/E43)/(E$18/E$43) -> 1 | BA18: =(F18/F43)/(F$18/F$43) -> 1 | BB18: =(BA18/AW18)^(1/($Z$7-$V$7))-1 -> 0 | BD18: World | BE18: =1-(ABS(C18-I18)/(C18+I18)) -> 0.95398112 | BF18: =1-(ABS(D18-J18)/(D18+J18)) -> 0.94991795 | BG18: =1-(ABS(E18-K18)/(E18+K18)) -> 0.94891778 | BH18: =1-(ABS(F18-L18)/(F18+L18)) -> 0.95361866 | BI18: =1-(ABS(G18-M18)/(G18+M18)) -> 0.93171317 | BJ18: =(BI18/BE18)^(1/($Z$7-$V$7))-1 -> -0.0058873204 | BL18: World | BT18: World | BU18: =+C68 -> 0.068 | BV18: =+D68 -> 0.063 | BW18: =+E68 -> 0.064 | BX18: =+F68 -> 0.073 | BY18: =+G68 -> 0.069 | BZ18: =(BY18/BU18)^(1/($Z$7-$V$7))-1 -> 0.0036563681
V30: =+V6 -> Trade openness index (country level) | AE30: =+AE6 -> Export growth | AN30: =+AN6 -> Trade competitiveness index | AW30: =+AW6 -> Revealed comparative advantage index | BE30: =+BE6 -> Intra-industry trade | BM30: =+BM6 -> Export diversification | BU30: =+BU6 -> Export concentration
A31: TOTAL ALL PRODUCTS | B31: export | H31: import | V31: explain that a higher index indicates a more open economy, heavily depend on international trade. | AE31: explain that export growth refers to the change in a country's exports over a specific period. | AN31: explain that the TCI measures a country's ability to participate in and benefit from international trade. It is a basic measure of world market power. | AW31: explain that it measures a country's comparative advantage in exporting specific goods or services compared to the world average (in terms of labor costs and skills, resource endowments, technology and innovation etc). | BE31: explain that countries both import and export similar products within the same industry or the level of IIT between two countries for a specific product (economies of scale and scope, product differentiation). | BM31: explain how reliant a country's trade is on a limited number of partners or products. Higher values indicate greater concentration, while lower values signify more diversification. | BU31: explain how a country's reliance on a diverse range of products and trading partners. Higher values indicate better diversification, while lower values indicate greater concentration.
A32: Economy | B32: 2018 | C32: =+B32+1 -> 2019 | D32: =+C32+1 -> 2020 | E32: =+D32+1 -> 2021 | F32: =+E32+1 -> 2022 | G32: =+F32+1 -> 2023 | H32: 2018 | I32: =+H32+1 -> 2019 | J32: =+I32+1 -> 2020 | K32: =+J32+1 -> 2021 | L32: =+K32+1 -> 2022 | M32: =+L32+1 -> 2023 | U32: Explain: | AD32: Explain: The Trade Openness Index shows how much a country's economy depends on international trade. A higher index means the country trades more with other nations, relying heavily on exports and imports. For example, Sweden (8.85) and France (7.11) have high scores in 2023, meaning they are very open to trade. In contrast, the UK (1.90) and Switzerland (3.93) trade less compared to their overall economy. Countries like Iceland and Germany have increased their trade openness, while Switzerland and the UK have become less dependent on trade. The world average (4.25) suggests a moderate level of trade openness globally. | AM32: Explain:The Trade Competitiveness Index (TCI) measures how well a country competes in global trade and benefits from international markets. A higher TCI means a country has a strong position in global trade, selling more goods and services to the world. It reflects market power and the ability to attract demand for exports. For example, Italy (7.578) and Germany (4.096) have high TCI scores in 2023, showing strong global trade positions. France (4.004) has also grown in competitiveness, while the UK (0.947) and the US (1.504) have seen declines, meaning they are less competitive than before. Iceland (0.001) has the lowest score, indicating minimal global trade influence. | AV32: Explain:The Revealed Comparative Advantage (RCA) Index measures how competitive a country is in exporting specific goods or services compared to the world average. A higher RCA means the country has a stronger advantage in certain industries due to factors like lower labor costs, skilled workers, natural resources, advanced technology, or innovation. For example, if a country has a high RCA in a particular sector, it means it specializes in producing and exporting those goods more efficiently than other countries. This can be due to access to cheap raw materials, a well-developed workforce, or advanced manufacturing techniques. A lower RCA suggests the country does not have a strong competitive edge in that sector and relies more on imports. | BD32: Explain:Intra-Industry Trade (IIT) refers to a situation where countries both import and export similar goods within the same industry. This happens because of factors like economies of scale, where producing in larger quantities lowers costs, and product differentiation, where consumers demand variety in similar products, such as different car models or types of electronics. A higher IIT index means a country is actively trading similar products with others, showing strong industry integration in global markets. For example, European countries like France (0.884) and Sweden (0.798) have high IIT values, indicating they export and import similar goods within industries like automobiles or machinery. In contrast, the United States (0.195) and Iceland (0.040) have low IIT values, meaning they engage less in this type of trade, either due to specialization or reliance on different industries. | BL32: Explain:Export Diversification measures how dependent a country's trade is on a small number of products or trading partners. A higher value means the country’s exports are more concentrated, relying on fewer products or markets, which can make it more vulnerable to economic shocks. A lower value indicates more diversification, meaning the country exports a wider variety of goods to different markets, reducing risk. For example, Iceland (0.783) and Switzerland (0.674) have high values, meaning their exports are more concentrated in specific industries or markets. In contrast, the United States (0.219) and Germany (0.325) have lower values, showing they export a broader range of goods across multiple markets, making their economies more resilient to trade disruptions. The UK (0.372) has seen an increase, indicating its exports have become more concentrated over time. | BT32: Explain:The Export Concentration Index measures how much a country's exports are dominated by a few products or trading partners. A higher index value indicates greater concentration, meaning the country relies heavily on a limited range of exports or markets. Conversely, a lower index value signifies more diversification, with exports spread across a wider array of products and destinations. For instance, in 2023, Iceland had an index of 0.432, suggesting a higher concentration in its exports, while France had an index of 0.070, indicating a more diversified export portfolio.
A33: Finland | B33: 75258290 | C33: 72839176 | D33: 65606976 | E33: 81500265 | F33: 86228240 | G33: 82567753 | H33: 78352161 | I33: 73719857 | J33: 68266522 | K33: 86263574 | L33: 97374453 | M33: 83093615
A34: France | B34: 569000000 | C34: 556000000 | D34: 488000000 | E34: 585000000 | F34: 618000000 | G34: 640000000 | H34: 659000000 | I34: 643000000 | J34: 581000000 | K34: 716000000 | L34: 819000000 | M34: 777000000
A35: Germany | B35: 1560000000 | C35: 1490000000 | D35: 1390000000 | E35: 1640000000 | F35: 1690000000 | G35: 1700000000 | H35: 1290000000 | I35: 1240000000 | J35: 1170000000 | K35: 1420000000 | L35: 1590000000 | M35: 1470000000
A36: Iceland | B36: 5561476 | C36: 5228361 | D36: 4580415 | E36: 5973743 | F36: 7403797 | G36: 6807540 | H36: 7686033 | I36: 6579004 | J36: 5696680 | K36: 7838072 | L36: 9643943 | M36: 9470151
A37: Italy | B37: 550000000 | C37: 538000000 | D37: 499000000 | E37: 616000000 | F37: 659000000 | G37: 677000000 | H37: 504000000 | I37: 475000000 | J37: 426000000 | K37: 568000000 | L37: 695000000 | M37: 640000000
A38: Spain | B38: 346000000 | C38: 337000000 | D38: 312000000 | E38: 392000000 | F38: 424000000 | G38: 420000000 | H38: 391000000 | I38: 375000000 | J38: 330000000 | K38: 426000000 | L38: 499000000 | M38: 469000000
A39: Sweden | B39: 166000000 | C39: 161000000 | D39: 155000000 | E39: 190000000 | F39: 198000000 | G39: 198000000 | H39: 170000000 | I39: 159000000 | J39: 149000000 | K39: 187000000 | L39: 203000000 | M39: 193000000
A40: Switzerland | B40: 311000000 | C40: 314000000 | D40: 319000000 | E40: 380000000 | F40: 400000000 | G40: 420000000 | H40: 279000000 | I40: 276000000 | J40: 290000000 | K40: 323000000 | L40: 356000000 | M40: 365000000
A41: United Kingdom | B41: 491000000 | C41: 468000000 | D41: 396000000 | E41: 471000000 | F41: 535000000 | G41: 521000000 | H41: 672000000 | I41: 692000000 | J41: 634000000 | K41: 688000000 | L41: 822000000 | M41: 792000000
A42: United States | B42: 1670000000 | C42: 1640000000 | D42: 1430000000 | E42: 1750000000 | F42: 2060000000 | G42: 2020000000 | H42: 2610000000 | I42: 2570000000 | J42: 2410000000 | K42: 2930000000 | L42: 3370000000 | M42: 3170000000
A43: World | B43: 17589979029 | C43: 17814032484 | D43: 19384753989 | E43: 19618926996 | F43: 18827856013 | G43: 19120698758 | H43: 17515362832 | I43: 17702611132 | J43: 22250724814 | K43: 22482671300 | L43: 24790423022 | M43: 25482701523
A56: TOTAL ALL PRODUCTS | B56: export concentration | H56: export diversification
A57: Economy | B57: 2018 | C57: =+B57+1 -> 2019 | D57: =+C57+1 -> 2020 | E57: =+D57+1 -> 2021 | F57: =+E57+1 -> 2022 | G57: =+F57+1 -> 2023 | H57: 2018 | I57: =+H57+1 -> 2019 | J57: =+I57+1 -> 2020 | K57: =+J57+1 -> 2021 | L57: =+K57+1 -> 2022 | M57: =+L57+1 -> 2023
A58: Australia | B58: 0.143 | C58: 0.134 | D58: 0.127 | E58: 0.128 | F58: 0.126 | G58: 0.119 | H58: 0.517 | I58: 0.516 | J58: 0.522 | K58: 0.518 | L58: 0.511 | M58: 0.511
A59: Belgium | B59: 0.089 | C59: 0.093 | D59: 0.08 | E59: 0.068 | F59: 0.065 | G59: 0.07 | H59: 0.333 | I59: 0.335 | J59: 0.33 | K59: 0.329 | L59: 0.332 | M59: 0.317
A60: Brazil | B60: 0.093 | C60: 0.091 | D60: 0.085 | E60: 0.082 | F60: 0.088 | G60: 0.097 | H60: 0.311 | I60: 0.304 | J60: 0.293 | K60: 0.303 | L60: 0.325 | M60: 0.309
A61: Chile | B61: 0.46 | C61: 0.442 | D61: 0.466 | E61: 0.48 | F61: 0.466 | G61: 0.432 | H61: 0.793 | I61: 0.793 | J61: 0.824 | K61: 0.8 | L61: 0.783 | M61: 0.794
A62: China | B62: 0.053 | C62: 0.056 | D62: 0.058 | E62: 0.053 | F62: 0.06 | G62: 0.062 | H62: 0.357 | I62: 0.355 | J62: 0.345 | K62: 0.353 | L62: 0.366 | M62: 0.354
A63: Denmark | B63: 0.097 | C63: 0.099 | D63: 0.099 | E63: 0.089 | F63: 0.09 | G63: 0.092 | H63: 0.341 | I63: 0.342 | J63: 0.358 | K63: 0.355 | L63: 0.354 | M63: 0.328
A64: France | B64: 0.097 | C64: 0.096 | D64: 0.093 | E64: 0.088 | F64: 0.092 | G64: 0.095 | H64: 0.361 | I64: 0.354 | J64: 0.347 | K64: 0.353 | L64: 0.37 | M64: 0.348
A65: Germany | B65: 0.246 | C65: 0.25 | D65: 0.273 | E65: 0.271 | F65: 0.28 | G65: 0.286 | H65: 0.636 | I65: 0.64 | J65: 0.644 | K65: 0.66 | L65: 0.674 | M65: 0.671
A66: India | B66: 0.112 | C66: 0.105 | D66: 0.097 | E66: 0.114 | F66: 0.14 | G66: 0.139 | H66: 0.324 | I66: 0.32 | J66: 0.323 | K66: 0.365 | L66: 0.372 | M66: 0.368
A67: Indonesia | B67: 0.099 | C67: 0.101 | D67: 0.083 | E67: 0.083 | F67: 0.094 | G67: 0.097 | H67: 0.24 | I67: 0.23 | J67: 0.232 | K67: 0.228 | L67: 0.219 | M67: 0.224
A68: World | B68: 0.07 | C68: 0.068 | D68: 0.063 | E68: 0.064 | F68: 0.073 | G68: 0.069 | H68: 0 | I68: 0 | J68: 0 | K68: 0 | L68: 0 | M68: 0

Sheet Trade index
B1: 2023 | C1: higher, higher | D1: higher, higher | E1: higher, higher | F1: higher, higher | G1: higher, higher | H1: higher, lower | L1: =+B1-1 -> 2022 | M1: higher, higher | N1: higher, higher | O1: higher, higher | P1: higher, higher | Q1: higher, higher | R1: higher, lower | V1: =+L1-1 -> 2021 | W1: higher, higher | X1: higher, higher | Y1: higher, higher | Z1: higher, higher | AA1: higher, higher | AB1: higher, lower | AF1: =+V1-1 -> 2020 | AG1: higher, higher | AH1: higher, higher | AI1: higher, higher | AJ1: higher, higher | AK1: higher, higher | AL1: higher, lower | AP1: =+AF1-1 -> 2019 | AQ1: higher, higher | AR1: higher, higher | AS1: higher, higher | AT1: higher, higher | AU1: higher, higher | AV1: higher, lower
B2: Economy | C2: OPEN | D2: EXPGW | E2: TC | F2: RCA | G2: IIT | H2: DIVER | L2: Economy | M2: OPEN | N2: EXPGW | O2: TC | P2: RCA | Q2: IIT | R2: DIVER | V2: Economy | W2: OPEN | X2: EXPGW | Y2: TC | Z2: RCA | AA2: IIT | AB2: DIVER | AF2: Economy | AG2: OPEN | AH2: EXPGW | AI2: TC | AJ2: RCA | AK2: IIT | AL2: DIVER | AP2: Economy | AQ2: OPEN | AR2: EXPGW | AS2: TC | AT2: RCA | AU2: IIT | AV2: DIVER
B3: Finland | C3: 5.4493871 | D3: -0.068978315 | E3: 0.052678237 | F3: =+'Trade indicators'!BA8 -> 0.12199008 | G3: =+'Trade indicators'!BI8 -> 0.2301683 | H3: ='Trade indicators'!BQ8 -> 0.511 | L3: Finland | M3: 6.4877277 | N3: 0.084651216 | O3: 0.055257123 | P3: 0.12065341 | Q3: 0.22185497 | R3: 0.518 | V3: Finland | W3: 5.6486141 | X3: 0.26447062 | Y3: 0.055106603 | Z3: 0.13265385 | AA3: 0.24151053 | AB3: 0.522 | AF3: Finland | AG3: 4.9218198 | AH3: -0.25020446 | AI3: 0.051456765 | AJ3: 0.15203821 | AK3: 0.20467331 | AL3: 0.516 | AP3: Finland | AQ3: 5.4482912 | AR3: 0.10282003 | AS3: 0.059274589 | AT3: 0.14496587 | AU3: 0.25821302 | AV3: 0.517
B4: France | C4: 4.6611842 | D4: 0.083869433 | E4: 4.004485 | F4: =+'Trade indicators'!BA9 -> 1.1963836 | G4: =+'Trade indicators'!BI9 -> 0.88354 | H4: ='Trade indicators'!BQ9 -> 0.332 | L4: France | M4: 5.1690647 | N4: 0.22558666 | O4: 3.6081662 | P4: 1.0992562 | Q4: 0.82173714 | R4: 0.329 | V4: France | W4: 4.3952703 | X4: 0.14329745 | Y4: 3.1845494 | Z4: 1.0679905 | AA4: 0.76723029 | AB4: 0.33 | AF4: France | AG4: 4.0339623 | AH4: -0.17007205 | AI4: 3.2887915 | AJ4: 1.3064019 | AK4: 0.77424933 | AL4: 0.335 | AP4: France | AQ4: 4.3919414 | AR4: -0.0065522747 | AS4: 3.4226688 | AT4: 1.0966103 | AU4: 0.78517879 | AV4: 0.333
B5: Germany | C5: 7.1076233 | D5: -0.013909614 | E5: 4.0956189 | F5: =+'Trade indicators'!BA10 -> 0.4606535 | G5: =+'Trade indicators'!BI10 -> 0.77798143 | H5: ='Trade indicators'!BQ10 -> 0.325 | L5: Germany | M5: 8.0392157 | N5: 0.039507767 | O5: 4.0562027 | P5: 0.45189113 | Q5: 0.71581516 | R5: 0.303 | V5: Germany | W5: 7.1495327 | X5: 0.1581622 | Y5: 4.2208255 | Z5: 0.50492724 | AA5: 0.74883147 | AB5: 0.293 | AF5: Germany | AG5: 6.5809769 | AH5: -0.074319103 | AI5: 4.303042 | AJ5: 0.60009648 | AK5: 0.73615033 | AL5: 0.304 | AP5: Germany | AQ5: 7.0179949 | AR5: 0.0056380007 | AS5: 4.0149784 | AT5: 0.48001984 | AU5: 0.74855601 | AV5: 0.311
B6: Iceland | C6: 5.3545036 | D6: 0.13559322 | E6: 0.0012059596 | F6: =+'Trade indicators'!BA11 -> 0.033872428 | G6: =+'Trade indicators'!BI11 -> 0.039831558 | H6: ='Trade indicators'!BQ11 -> 0.783 | L6: Iceland | M6: 6.0668114 | N6: -0.045822102 | O6: 0.0010371148 | P6: 0.026373829 | Q6: 0.033264424 | R6: 0.8 | V6: Iceland | W6: 5.3952402 | X6: 0.49596774 | Y6: 0.0011757174 | Z6: 0.038612833 | AA6: 0.037634409 | AB6: 0.824 | AF6: Iceland | AG6: 4.7579144 | AH6: 0.064377682 | AI6: 0.00092795795 | AJ6: 0.039272067 | AK6: 0.035043097 | AL6: 0.793 | AP6: Iceland | AQ6: 4.7803097 | AR6: 0.22631579 | AS6: 0.00075301125 | AT6: 0.025656543 | AU6: 0.034151704 | AV6: 0.793
B7: Italy | C7: 5.9058296 | D7: -0.014852279 | E7: 7.5782504 | F7: =+'Trade indicators'!BA12 -> 2.1403463 | G7: =+'Trade indicators'!BI12 -> 0.5743458 | H7: ='Trade indicators'!BQ12 -> 0.366 | L7: Italy | M7: 6.604878 | N7: 0.010474959 | O7: 7.512499 | P7: 2.1463467 | Q7: 0.56332297 | R7: 0.353 | V7: Italy | W7: 5.4814815 | X7: 0.19195724 | Y7: 8.0420052 | Z7: 2.5612908 | AA7: 0.51112037 | AB7: 0.345 | AF7: Italy | AG7: 4.8684211 | AH7: -0.092796987 | AI7: 7.9662009 | AJ7: 3.0946462 | AK7: 0.52288886 | AL7: 0.355 | AP7: Italy | AQ7: 5.039801 | AR7: 0.015951188 | AS7: 7.5843034 | AT7: 2.511283 | AU7: 0.57284501 | AV7: 0.357
B8: Spain | C8: 5.55625 | D8: 0.057502094 | E8: 1.2572729 | F8: =+'Trade indicators'!BA13 -> 0.57237945 | G8: =+'Trade indicators'!BI13 -> 0.75823789 | H8: ='Trade indicators'!BQ13 -> 0.354 | L8: Spain | M8: 6.5 | N8: 0.054955001 | O8: 1.1610881 | P8: 0.51558488 | Q8: 0.70569151 | R8: 0.355 | V8: Spain | W8: 5.6413793 | X8: 0.27306399 | Y8: 1.19052 | Z8: 0.59583484 | AA8: 0.75548888 | AB8: 0.358 | AF8: Spain | AG8: 5.015625 | AH8: -0.24679541 | AI8: 1.1041652 | AJ8: 0.6860247 | AK8: 0.72036295 | AL8: 0.342 | AP8: Spain | AQ8: 5.1223022 | AR8: -0.11290491 | AS8: 1.2661642 | AT8: 0.66930236 | AU8: 0.73471225 | AV8: 0.341
B9: Sweden | C9: 6.6271186 | D9: 0.016371681 | E9: 0.62016924 | F9: =+'Trade indicators'!BA14 -> 0.59889239 | G9: =+'Trade indicators'!BI14 -> 0.79758483 | H9: ='Trade indicators'!BQ14 -> 0.37 | L9: Sweden | M9: 6.78511 | N9: 0.078335737 | O9: 0.59590153 | P9: 0.56664385 | Q9: 0.74232222 | R9: 0.353 | V9: Sweden | W9: 5.890625 | X9: 0.23618156 | Y9: 0.59775881 | Z9: 0.61723087 | AA9: 0.73463585 | AB9: 0.347 | AF9: Sweden | AG9: 5.5575868 | AH9: 0.0079866823 | AI9: 0.57094109 | AJ9: 0.71403566 | AK9: 0.75203304 | AL9: 0.354 | AP9: Sweden | AQ9: 5.9925094 | AR9: 0.13101269 | AS9: 0.48922139 | AT9: 0.5413047 | AU9: 0.69626311 | AV9: 0.361
B10: Switzerland | C10: 8.8500564 | D10: 0.25845482 | E10: 0.3198193 | F10: =+'Trade indicators'!BA15 -> 0.14559925 | G10: =+'Trade indicators'!BI15 -> 0.41821784 | H10: ='Trade indicators'!BQ15 -> 0.674 | L10: Switzerland | M10: 9.2420538 | N10: -0.063405196 | O10: 0.24818977 | P10: 0.11682203 | Q10: 0.35369023 | R10: 0.66 | V10: Switzerland | W10: 8.6469865 | X10: 0.15859048 | Y10: 0.28664054 | Z10: 0.14798894 | AA10: 0.37437914 | AB10: 0.644 | AF10: Switzerland | AG10: 8.2075472 | AH10: -0.056260049 | AI10: 0.29211592 | AJ10: 0.17751082 | AK10: 0.37478037 | AL10: 0.64 | AP10: Switzerland | AQ10: 8.1830791 | AR10: -0.039567635 | AS10: 0.26734485 | AT10: 0.15167165 | AU10: 0.3848736 | AV10: 0.636
B11: United Kingdom | C11: 3.9311377 | D11: -0.10028252 | E11: 0.94674731 | F11: =+'Trade indicators'!BA16 -> 0.34745624 | G11: =+'Trade indicators'!BI16 -> 0.41973573 | H11: ='Trade indicators'!BQ16 -> 0.372 | L11: United Kingdom | M11: 4.3915858 | N11: 0.10922114 | O11: 1.0276489 | P11: 0.36165281 | Q11: 0.42567891 | R11: 0.365 | V11: United Kingdom | W11: 3.6910828 | X11: -0.16683792 | Y11: 1.0021486 | Z11: 0.41743268 | AA11: 0.4466822 | AB11: 0.323 | AF11: United Kingdom | AG11: 3.8148148 | AH11: -0.17469243 | AI11: 1.4202022 | AJ11: 0.69520886 | AK11: 0.51224697 | AL11: 0.32 | AP11: United Kingdom | AQ11: 4.0701754 | AR11: -0.15004593 | AS11: 1.4862891 | AT11: 0.56574363 | AU11: 0.49586477 | AV11: 0.324
B12: United States | C12: 1.9010989 | D12: -0.098897939 | E12: 1.5043476 | F12: =+'Trade indicators'!BA17 -> 0.14239692 | G12: =+'Trade indicators'!BI17 -> 0.1948326 | H12: ='Trade indicators'!BQ17 -> 0.219 | L12: United States | M12: 2.1128405 | N12: -0.28972901 | O12: 1.6303884 | P12: 0.14901319 | Q12: 0.18033921 | R12: 0.228 | V12: United States | W12: 1.9830508 | X12: 0.43511462 | Y12: 2.4829757 | Z12: 0.27836182 | AA12: 0.2638824 | AB12: 0.232 | AF12: United States | AG12: 1.8028169 | AH12: -0.28655156 | AI12: 2.0428358 | AJ12: 0.27692217 | AK12: 0.22160889 | AL12: 0.23 | AP12: United States | AQ12: 1.9581395 | AR12: -0.083268842 | AS12: 2.4730893 | AT12: 0.26863228 | AU12: 0.26236299 | AV12: 0.24
C13: =+'Trade indicators'!Z19 | D13: ='Trade indicators'!AI19 | E13: =+'Trade indicators'!AR19 | F13: =+'Trade indicators'!BA19 | G13: =+'Trade indicators'!BI19 | H13: ='Trade indicators'!BQ19
C14: =+'Trade indicators'!Z20 | D14: ='Trade indicators'!AI20 | E14: =+'Trade indicators'!AR20 | F14: =+'Trade indicators'!BA20 | G14: =+'Trade indicators'!BI20 | H14: ='Trade indicators'!BQ20
C15: =+'Trade indicators'!Z21 | D15: ='Trade indicators'!AI21 | E15: =+'Trade indicators'!AR21 | F15: =+'Trade indicators'!BA21 | G15: =+'Trade indicators'!BI21 | H15: ='Trade indicators'!BQ21
C16: =+'Trade indicators'!Z22 | D16: ='Trade indicators'!AI22 | E16: =+'Trade indicators'!AR22 | F16: =+'Trade indicators'!BA22 | G16: =+'Trade indicators'!BI22 | H16: ='Trade indicators'!BQ22
C17: =+'Trade indicators'!Z23 | D17: ='Trade indicators'!AI23 | E17: =+'Trade indicators'!AR23 | F17: =+'Trade indicators'!BA23 | G17: =+'Trade indicators'!BI23 | H17: ='Trade indicators'!BQ23
C18: =+'Trade indicators'!Z24 | D18: ='Trade indicators'!AI24 | E18: =+'Trade indicators'!AR24 | F18: =+'Trade indicators'!BA24 | G18: =+'Trade indicators'!BI24 | H18: ='Trade indicators'!BQ24
C19: =+'Trade indicators'!Z25 | D19: ='Trade indicators'!AI25 | E19: =+'Trade indicators'!AR25 | F19: =+'Trade indicators'!BA25 | G19: =+'Trade indicators'!BI25 | H19: ='Trade indicators'!BQ25
C20: =+'Trade indicators'!Z26 | D20: ='Trade indicators'!AI26 | E20: =+'Trade indicators'!AR26 | F20: =+'Trade indicators'!BA26 | G20: =+'Trade indicators'!BI26 | H20: ='Trade indicators'!BQ26
C21: =+'Trade indicators'!Z27 | D21: ='Trade indicators'!AI27 | E21: =+'Trade indicators'!AR27 | F21: =+'Trade indicators'!BA27 | G21: =+'Trade indicators'!BI27 | H21: ='Trade indicators'!BQ27
C22: =+'Trade indicators'!Z28 | D22: ='Trade indicators'!AI28 | E22: =+'Trade indicators'!AR28 | F22: =+'Trade indicators'!BA28 | G22: =+'Trade indicators'!BI28 | H22: ='Trade indicators'!BQ28
C23: =+'Trade indicators'!Z29 | D23: ='Trade indicators'!AI29 | E23: =+'Trade indicators'!AR29 | F23: =+'Trade indicators'!BA29 | G23: =+'Trade indicators'!BI29 | H23: ='Trade indicators'!BQ29
B24: Sum | C24: =SUM(C3:C23) -> 55.344189 | D24: =SUM(D3:D23) -> 0.25487058 | E24: =SUM(E3:E23) -> 20.380595 | F24: =SUM(F3:F23) -> 5.7599701 | G24: =SUM(G3:G23) -> 5.094476 | H24: =SUM(H3:H23) -> 4.306 | L24: Sum | M24: =SUM(M3:M23) -> 61.399288 | N24: =SUM(N3:N23) -> 0.20377616 | O24: =SUM(O3:O23) -> 19.896379 | P24: =SUM(P3:P23) -> 5.5542381 | Q24: =SUM(Q3:Q23) -> 4.7637167 | R24: =SUM(R3:R23) -> 4.264 | V24: Sum | W24: =SUM(W3:W23) -> 53.923263 | X24: =SUM(X3:X23) -> 2.189968 | Y24: =SUM(Y3:Y23) -> 21.063706 | Z24: =SUM(Z3:Z23) -> 6.3623243 | AA24: =SUM(AA3:AA23) -> 4.8813955 | AB24: =SUM(AB3:AB23) -> 4.218 | AF24: Sum | AG24: =SUM(AG3:AG23) -> 49.561485 | AH24: =SUM(AH3:AH23) -> -1.2793277 | AI24: =SUM(AI3:AI23) -> 21.040679 | AJ24: =SUM(AJ3:AJ23) -> 7.7421571 | AK24: =SUM(AK3:AK23) -> 4.8540371 | AL24: =SUM(AL3:AL23) -> 4.189 | AP24: Sum | AQ24: =SUM(AQ3:AQ23) -> 52.004544 | AR24: =SUM(AR3:AR23) -> 0.089398115 | AS24: =SUM(AS3:AS23) -> 21.064087 | AT24: =SUM(AT3:AT23) -> 6.4551902 | AU24: =SUM(AU3:AU23) -> 4.9730213 | AV24: =SUM(AV3:AV23) -> 4.213
B25: min | C25: =MIN(C3:C23) -> 1.9010989 | D25: =MIN(D3:D23) -> -0.10028252 | E25: =MIN(E3:E23) -> 0.0012059596 | F25: =MIN(F3:F23) -> 0.033872428 | G25: =MIN(G3:G23) -> 0.039831558 | H25: =MIN(H3:H23) -> 0.219 | L25: min | M25: =MIN(M3:M23) -> 2.1128405 | N25: =MIN(N3:N23) -> -0.28972901 | O25: =MIN(O3:O23) -> 0.0010371148 | P25: =MIN(P3:P23) -> 0.026373829 | Q25: =MIN(Q3:Q23) -> 0.033264424 | R25: =MIN(R3:R23) -> 0.228 | V25: min | W25: =MIN(W3:W23) -> 1.9830508 | X25: =MIN(X3:X23) -> -0.16683792 | Y25: =MIN(Y3:Y23) -> 0.0011757174 | Z25: =MIN(Z3:Z23) -> 0.038612833 | AA25: =MIN(AA3:AA23) -> 0.037634409 | AB25: =MIN(AB3:AB23) -> 0.232 | AF25: min | AG25: =MIN(AG3:AG23) -> 1.8028169 | AH25: =MIN(AH3:AH23) -> -0.28655156 | AI25: =MIN(AI3:AI23) -> 0.00092795795 | AJ25: =MIN(AJ3:AJ23) -> 0.039272067 | AK25: =MIN(AK3:AK23) -> 0.035043097 | AL25: =MIN(AL3:AL23) -> 0.23 | AP25: min | AQ25: =MIN(AQ3:AQ23) -> 1.9581395 | AR25: =MIN(AR3:AR23) -> -0.15004593 | AS25: =MIN(AS3:AS23) -> 0.00075301125 | AT25: =MIN(AT3:AT23) -> 0.025656543 | AU25: =MIN(AU3:AU23) -> 0.034151704 | AV25: =MIN(AV3:AV23) -> 0.24
B26: max | C26: =MAX(C3:C23) -> 8.8500564 | D26: =MAX(D3:D23) -> 0.25845482 | E26: =MAX(E3:E23) -> 7.5782504 | F26: =MAX(F3:F23) -> 2.1403463 | G26: =MAX(G3:G23) -> 0.88354 | H26: =MAX(H3:H23) -> 0.783 | L26: max | M26: =MAX(M3:M23) -> 9.2420538 | N26: =MAX(N3:N23) -> 0.22558666 | O26: =MAX(O3:O23) -> 7.512499 | P26: =MAX(P3:P23) -> 2.1463467 | Q26: =MAX(Q3:Q23) -> 0.82173714 | R26: =MAX(R3:R23) -> 0.8 | V26: max | W26: =MAX(W3:W23) -> 8.6469865 | X26: =MAX(X3:X23) -> 0.49596774 | Y26: =MAX(Y3:Y23) -> 8.0420052 | Z26: =MAX(Z3:Z23) -> 2.5612908 | AA26: =MAX(AA3:AA23) -> 0.76723029 | AB26: =MAX(AB3:AB23) -> 0.824 | AF26: max | AG26: =MAX(AG3:AG23) -> 8.2075472 | AH26: =MAX(AH3:AH23) -> 0.064377682 | AI26: =MAX(AI3:AI23) -> 7.9662009 | AJ26: =MAX(AJ3:AJ23) -> 3.0946462 | AK26: =MAX(AK3:AK23) -> 0.77424933 | AL26: =MAX(AL3:AL23) -> 0.793 | AP26: max | AQ26: =MAX(AQ3:AQ23) -> 8.1830791 | AR26: =MAX(AR3:AR23) -> 0.22631579 | AS26: =MAX(AS3:AS23) -> 7.5843034 | AT26: =MAX(AT3:AT23) -> 2.511283 | AU26: =MAX(AU3:AU23) -> 0.78517879 | AV26: =MAX(AV3:AV23) -> 0.793
B28: Step 1: To eliminate the differences in the units of the indicators, the data are standardized. | L28: Step 1: To eliminate the differences in the units of the indicators, the data are standardized. | V28: Step 1: To eliminate the differences in the units of the indicators, the data are standardized. | AF28: Step 1: To eliminate the differences in the units of the indicators, the data are standardized. | AP28: Step 1: To eliminate the differences in the units of the indicators, the data are standardized.
B29: Economy | C29: OPEN | D29: EXPGW | E29: TC | F29: RCA | G29: IIT | H29: DIVER | L29: Economy | M29: OPEN | N29: EXPGW | O29: TC | P29: RCA | Q29: IIT | R29: DIVER | V29: Economy | W29: OPEN | X29: EXPGW | Y29: TC | Z29: RCA | AA29: IIT | AB29: DIVER | AF29: Economy | AG29: OPEN | AH29: EXPGW | AI29: TC | AJ29: RCA | AK29: IIT | AL29: DIVER | AP29: Economy | AQ29: OPEN | AR29: EXPGW | AS29: TC | AT29: RCA | AU29: IIT | AV29: DIVER
B30: Finland | C30: =(C3-C$25)/(C$26-C$25) -> 0.51062166 | D30: =(D3-D$25)/(D$26-D$25) -> 0.087262193 | E30: =(E3-E$25)/(E$26-E$25) -> 0.0067931867 | F30: =(F3-F$25)/(F$26-F$25) -> 0.041831829 | G30: =(G3-G$25)/(G$26-G$25) -> 0.2255954 | H30: =(H$26-H3)/(H$26-H$25) -> 0.4822695 | L30: Finland | M30: =(M3-M$25)/(M$26-M$25) -> 0.61365637 | N30: =(N3-N$25)/(N$26-N$25) -> 0.72650659 | O30: =(O3-O$25)/(O$26-O$25) -> 0.0072183031 | P30: =(P3-P$25)/(P$26-P$25) -> 0.044472071 | Q30: =(Q3-Q$25)/(Q$26-Q$25) -> 0.23918462 | R30: =(R$26-R3)/(R$26-R$25) -> 0.49300699 | V30: Finland | W30: =(W3-W$25)/(W$26-W$25) -> 0.55005982 | X30: =(X3-X$25)/(X$26-X$25) -> 0.65073153 | Y30: =(Y3-Y$25)/(Y$26-Y$25) -> 0.0067071296 | Z30: =(Z3-Z$25)/(Z$26-Z$25) -> 0.037278251 | AA30: =(AA3-AA$25)/(AA$26-AA$25) -> 0.27943706 | AB30: =(AB$26-AB3)/(AB$26-AB$25) -> 0.51013514 | AF30: Finland | AG30: =(AG3-AG$25)/(AG$26-AG$25) -> 0.48698427 | AH30: =(AH3-AH$25)/(AH$26-AH$25) -> 0.10357388 | AI30: =(AI3-AI$25)/(AI$26-AI$25) -> 0.0063436378 | AJ30: =(AJ3-AJ$25)/(AJ$26-AJ$25) -> 0.036907475 | AK30: =(AK3-AK$25)/(AK$26-AK$25) -> 0.22947617 | AL30: =(AL$26-AL3)/(AL$26-AL$25) -> 0.4920071 | AP30: Finland | AQ30: =(AQ3-AQ$25)/(AQ$26-AQ$25) -> 0.56067238 | AR30: =(AR3-AR$25)/(AR$26-AR$25) -> 0.67186951 | AS30: =(AS3-AS$25)/(AS$26-AS$25) -> 0.0077169103 | AT30: =(AT3-AT$25)/(AT$26-AT$25) -> 0.047999701 | AU30: =(AU3-AU$25)/(AU$26-AU$25) -> 0.29833986 | AV30: =(AV$26-AV3)/(AV$26-AV$25) -> 0.49909584
B31: France | C31: =(C4-C$25)/(C$26-C$25) -> 0.39719416 | D31: =(D4-D$25)/(D$26-D$25) -> 0.51333367 | E31: =(E4-E$25)/(E$26-E$25) -> 0.52834308 | F31: =(F4-F$25)/(F$26-F$25) -> 0.55187544 | G31: =(G4-G$25)/(G$26-G$25) -> 1 | H31: =(H$26-H4)/(H$26-H$25) -> 0.79964539 | L31: France | M31: =(M4-M$25)/(M$26-M$25) -> 0.42869026 | N31: =(N4-N$25)/(N$26-N$25) -> 1 | O31: =(O4-O$25)/(O$26-O$25) -> 0.48021665 | P31: =(P4-P$25)/(P$26-P$25) -> 0.50608306 | Q31: =(Q4-Q$25)/(Q$26-Q$25) -> 1 | R31: =(R$26-R4)/(R$26-R$25) -> 0.82342657 | V31: France | W31: =(W4-W$25)/(W$26-W$25) -> 0.3619812 | X31: =(X4-X$25)/(X$26-X$25) -> 0.46791297 | Y31: =(Y4-Y$25)/(Y$26-Y$25) -> 0.39590115 | Z31: =(Z4-Z$25)/(Z$26-Z$25) -> 0.40804956 | AA31: =(AA4-AA$25)/(AA$26-AA$25) -> 1 | AB31: =(AB$26-AB4)/(AB$26-AB$25) -> 0.83445946 | AF31: France | AG31: =(AG4-AG$25)/(AG$26-AG$25) -> 0.34835899 | AH31: =(AH4-AH$25)/(AH$26-AH$25) -> 0.33191736 | AI31: =(AI4-AI$25)/(AI$26-AI$25) -> 0.41277474 | AJ31: =(AJ4-AJ$25)/(AJ$26-AJ$25) -> 0.41472167 | AK31: =(AK4-AK$25)/(AK$26-AK$25) -> 1 | AL31: =(AL$26-AL4)/(AL$26-AL$25) -> 0.81349911 | AP31: France | AQ31: =(AQ4-AQ$25)/(AQ$26-AQ$25) -> 0.39097598 | AR31: =(AR4-AR$25)/(AR$26-AR$25) -> 0.38126527 | AS31: =(AS4-AS$25)/(AS$26-AS$25) -> 0.45122873 | AT31: =(AT4-AT$25)/(AT$26-AT$25) -> 0.43085869 | AU31: =(AU4-AU$25)/(AU$26-AU$25) -> 1 | AV31: =(AV$26-AV4)/(AV$26-AV$25) -> 0.8318264
B32: Germany | C32: =(C5-C$25)/(C$26-C$25) -> 0.7492526 | D32: =(D5-D$25)/(D$26-D$25) -> 0.24076921 | E32: =(E5-E$25)/(E$26-E$25) -> 0.54037072 | F32: =(F5-F$25)/(F$26-F$25) -> 0.2026045 | G32: =(G5-G$25)/(G$26-G$25) -> 0.87488739 | H32: =(H$26-H5)/(H$26-H$25) -> 0.81205674 | L32: Germany | M32: =(M5-M$25)/(M$26-M$25) -> 0.83128039 | N32: =(N5-N$25)/(N$26-N$25) -> 0.6389031 | O32: =(O5-O$25)/(O$26-O$25) -> 0.5398637 | P32: =(P5-P$25)/(P$26-P$25) -> 0.20071827 | Q32: =(Q5-Q$25)/(Q$26-Q$25) -> 0.86566184 | R32: =(R$26-R5)/(R$26-R$25) -> 0.86888112 | V32: Germany | W32: =(W5-W$25)/(W$26-W$25) -> 0.77528988 | X32: =(X5-X$25)/(X$26-X$25) -> 0.49033998 | Y32: =(Y5-Y$25)/(Y$26-Y$25) -> 0.52477791 | Z32: =(Z5-Z$25)/(Z$26-Z$25) -> 0.18484896 | AA32: =(AA5-AA$25)/(AA$26-AA$25) -> 0.97478217 | AB32: =(AB$26-AB5)/(AB$26-AB$25) -> 0.89695946 | AF32: Germany | AG32: =(AG5-AG$25)/(AG$26-AG$25) -> 0.7460361 | AH32: =(AH5-AH$25)/(AH$26-AH$25) -> 0.60477279 | AI32: =(AI5-AI$25)/(AI$26-AI$25) -> 0.54010881 | AJ32: =(AJ5-AJ$25)/(AJ$26-AJ$25) -> 0.18355343 | AK32: =(AK5-AK$25)/(AK$26-AK$25) -> 0.94845958 | AL32: =(AL$26-AL5)/(AL$26-AL$25) -> 0.86856128 | AP32: Germany | AQ32: =(AQ5-AQ$25)/(AQ$26-AQ$25) -> 0.81283606 | AR32: =(AR5-AR$25)/(AR$26-AR$25) -> 0.41365506 | AS32: =(AS5-AS$25)/(AS$26-AS$25) -> 0.52933325 | AT32: =(AT5-AT$25)/(AT$26-AT$25) -> 0.18279629 | AU32: =(AU5-AU$25)/(AU$26-AU$25) -> 0.95123641 | AV32: =(AV$26-AV5)/(AV$26-AV$25) -> 0.8716094
B33: Iceland | C33: =(C6-C$25)/(C$26-C$25) -> 0.49696731 | D33: =(D6-D$25)/(D$26-D$25) -> 0.65751656 | E33: =(E6-E$25)/(E$26-E$25) -> 0 | F33: =(F6-F$25)/(F$26-F$25) -> 0 | G33: =(G6-G$25)/(G$26-G$25) -> 0 | H33: =(H$26-H6)/(H$26-H$25) -> 0 | L33: Iceland | M33: =(M6-M$25)/(M$26-M$25) -> 0.55461532 | N33: =(N6-N$25)/(N$26-N$25) -> 0.47331553 | O33: =(O6-O$25)/(O$26-O$25) -> 0 | P33: =(P6-P$25)/(P$26-P$25) -> 0 | Q33: =(Q6-Q$25)/(Q$26-Q$25) -> 0 | R33: =(R$26-R6)/(R$26-R$25) -> 0 | V33: Iceland | W33: =(W6-W$25)/(W$26-W$25) -> 0.51203817 | X33: =(X6-X$25)/(X$26-X$25) -> 1 | Y33: =(Y6-Y$25)/(Y$26-Y$25) -> 0 | Z33: =(Z6-Z$25)/(Z$26-Z$25) -> 0 | AA33: =(AA6-AA$25)/(AA$26-AA$25) -> 0 | AB33: =(AB$26-AB6)/(AB$26-AB$25) -> 0 | AF33: Iceland | AG33: =(AG6-AG$25)/(AG$26-AG$25) -> 0.46139296 | AH33: =(AH6-AH$25)/(AH$26-AH$25) -> 1 | AI33: =(AI6-AI$25)/(AI$26-AI$25) -> 0 | AJ33: =(AJ6-AJ$25)/(AJ$26-AJ$25) -> 0 | AK33: =(AK6-AK$25)/(AK$26-AK$25) -> 0 | AL33: =(AL$26-AL6)/(AL$26-AL$25) -> 0 | AP33: Iceland | AQ33: =(AQ6-AQ$25)/(AQ$26-AQ$25) -> 0.45336508 | AR33: =(AR6-AR$25)/(AR$26-AR$25) -> 1 | AS33: =(AS6-AS$25)/(AS$26-AS$25) -> 0 | AT33: =(AT6-AT$25)/(AT$26-AT$25) -> 0 | AU33: =(AU6-AU$25)/(AU$26-AU$25) -> 0 | AV33: =(AV$26-AV6)/(AV$26-AV$25) -> 0
